File: ExpDat_20250310PQM.txt
#EXPORTTYPE:DATA ALL
#FILE:20250310PQM.ngb-ss5
#FORMAT:NETZSCH5
#FTYPE:ANSI
#IDENTITY:20250310PQM
#DECIMAL:POINT
#SEPARATOR:SEMICOLON
#MTYPE:DTA
#INSTRUMENT:NETZSCH STA 449F5
#PROJECT:
#DATE/TIME:10.03.2025 16:49
#CORR. FILE:
#TEMPCAL:TCALZERO.TCX
#SENSITIVITY:SENSZERO.EXX
#LABORATORY:
#OPERATOR:
#REMARK:DSC Al2O3
#SAMPLE:20250310PQM
#SAMPLE MASS /mg:16.83
#MATERIAL:
#REFERENCE:al2o3
#REFERENCE MASS /mg:0
#TYPE OF CRUCIBLE:Al2O3 3.4 ml, open
#SAMPLE CRUCIBLE MASS /mg:0
#REFERENCE CRUCIBLE MASS /mg:197.80
#PURGE 1 MFC:AIR(80/20),250.3 ml/min
#PURGE 2 MFC:NITROGEN,250.0 ml/min
#PROTECTIVE MFC:NITROGEN,250.0 ml/min
#DTA RANGE /¶ÃV:5000
#TG RANGE /mg:35000
#TAU-R:---
#CORR. CODE:000
#EXO:-1
#RANGE:20°„C/10.0(K/min)/800°„C
#SEGMENT:S1/1
#SEG. 1:20°„C/10.0(K/min)/800°„C

##Temp./°„C;Time/min;DTA/(uV/mg);Mass/%;Gas Flow(purge2)/(ml/min);Gas Flow(protective)/(ml/min);Sensit./(uV/mW)
 18.15400; 0.00000; 5.480654e-02; 99.92343;80.00000;20.00000;1.00000
 19.23400; 1.64553; 3.889899e-02; 99.96407;80.00000;20.00000;1.00000
 20.31400; 2.23012; 2.302740e-02;100.12186;80.00000;20.00000;1.00000
 21.39400; 2.63171; 8.140566e-03;100.17382;80.00000;20.00000;1.00000
 22.47400; 2.94935;-4.584134e-03;100.23268;80.00000;20.00000;1.00000
 23.55400; 3.21540;-1.622625e-02;100.24958;80.00000;20.00000;1.00000
 24.63400; 3.45075;-2.805779e-02;100.26118;80.00000;20.00000;1.00000
 25.71400; 3.66201;-3.886260e-02;100.28236;80.00000;20.00000;1.00000
 26.79400; 3.85598;-5.049113e-02;100.30128;80.00000;20.00000;1.00000
 27.87400; 4.03603;-6.078220e-02;100.29207;80.00000;20.00000;1.00000
 28.95400; 4.20367;-7.054250e-02;100.30276;80.00000;20.00000;1.00000
 30.03400; 4.36170;-8.000049e-02;100.29063;80.00000;20.00000;1.00000
 31.11400; 4.51256;-9.029552e-02;100.29198;80.00000;20.00000;1.00000
 32.19400; 4.65664;-9.940723e-02;100.29382;80.00000;20.00000;1.00000
 33.27400; 4.79503;     -0.10866;100.28963;80.00000;20.00000;1.00000
 34.35400; 4.92768;     -0.11718;100.27646;80.00000;20.00000;1.00000
 35.43400; 5.05503;     -0.12638;100.24974;80.00000;20.00000;1.00000
 36.51400; 5.17883;     -0.13387;100.25380;80.00000;20.00000;1.00000
 37.59400; 5.29948;     -0.14304;100.24459;80.00000;20.00000;1.00000
 38.67400; 5.41644;     -0.15162;100.21494;80.00000;20.00000;1.00000
 39.75400; 5.53013;     -0.15945;100.19478;80.00000;20.00000;1.00000
 40.83400; 5.64080;     -0.16884;100.16676;80.00000;20.00000;1.00000
 41.91400; 5.74986;     -0.17697;100.16147;80.00000;20.00000;1.00000
 42.99400; 5.85662;     -0.18521;100.13968;80.00000;20.00000;1.00000
 44.07400; 5.96019;     -0.19391;100.10896;80.00000;20.00000;1.00000
 45.15400; 6.06189;     -0.20199;100.07988;80.00000;20.00000;1.00000
 46.23400; 6.16182;     -0.20952;100.05268;80.00000;20.00000;1.00000
 47.31400; 6.25993;     -0.21831;100.02652;80.00000;20.00000;1.00000
 48.39400; 6.35647;     -0.22622; 99.99456;80.00000;20.00000;1.00000
 49.47400; 6.45158;     -0.23418; 99.96854;80.00000;20.00000;1.00000
 50.55400; 6.54503;     -0.24272; 99.93676;80.00000;20.00000;1.00000
 51.63400; 6.63713;     -0.25014; 99.89700;80.00000;20.00000;1.00000
 52.71400; 6.72838;     -0.25892; 99.87575;80.00000;20.00000;1.00000
 53.79400; 6.81828;     -0.26579; 99.83887;80.00000;20.00000;1.00000
 54.87400; 6.90688;     -0.27366; 99.80558;80.00000;20.00000;1.00000
 55.95400; 6.99402;     -0.28191; 99.76835;80.00000;20.00000;1.00000
 57.03400; 7.08030;     -0.28929; 99.72785;80.00000;20.00000;1.00000
 58.11400; 7.16576;     -0.29693; 99.69987;80.00000;20.00000;1.00000
 59.19400; 7.25068;     -0.30476; 99.65368;80.00000;20.00000;1.00000
 60.27400; 7.33449;     -0.31285; 99.62056;80.00000;20.00000;1.00000
 61.35400; 7.41769;     -0.31955; 99.59179;80.00000;20.00000;1.00000
 62.43400; 7.50006;     -0.32785; 99.54467;80.00000;20.00000;1.00000
 63.51400; 7.58162;     -0.33449; 99.50810;80.00000;20.00000;1.00000
 64.59400; 7.66286;     -0.34240; 99.45731;80.00000;20.00000;1.00000
 65.67400; 7.74333;     -0.35115; 99.42394;80.00000;20.00000;1.00000
 66.75400; 7.82328;     -0.35770; 99.38709;80.00000;20.00000;1.00000
 67.83400; 7.90274;     -0.36476; 99.34077;80.00000;20.00000;1.00000
 68.91400; 7.98168;     -0.37205; 99.30081;80.00000;20.00000;1.00000
 69.99400; 8.06012;     -0.37844; 99.25262;80.00000;20.00000;1.00000
 71.07400; 8.13805;     -0.38541; 99.21592;80.00000;20.00000;1.00000
 72.15400; 8.21571;     -0.39212; 99.16240;80.00000;20.00000;1.00000
 73.23400; 8.29274;     -0.39896; 99.12212;80.00000;20.00000;1.00000
 74.31400; 8.36952;     -0.40558; 99.07305;80.00000;20.00000;1.00000
 75.39400; 8.44605;     -0.41178; 99.01982;80.00000;20.00000;1.00000
 76.47400; 8.52215;     -0.41790; 98.97074;80.00000;20.00000;1.00000
 77.55400; 8.59797;     -0.42463; 98.92743;80.00000;20.00000;1.00000
 78.63400; 8.67345;     -0.43058; 98.85987;80.00000;20.00000;1.00000
 79.71400; 8.74851;     -0.43592; 98.81008;80.00000;20.00000;1.00000
 80.79400; 8.82316;     -0.44153; 98.74794;80.00000;20.00000;1.00000
 81.87400; 8.89750;     -0.44709; 98.68787;80.00000;20.00000;1.00000
 82.95400; 8.97151;     -0.45215; 98.62212;80.00000;20.00000;1.00000
 84.03400; 9.04530;     -0.45744; 98.56362;80.00000;20.00000;1.00000
 85.11400; 9.11896;     -0.46212; 98.50052;80.00000;20.00000;1.00000
 86.19400; 9.19233;     -0.46715; 98.42222;80.00000;20.00000;1.00000
 87.27400; 9.26537;     -0.47027; 98.35588;80.00000;20.00000;1.00000
 88.35400; 9.33809;     -0.47495; 98.28486;80.00000;20.00000;1.00000
 89.43400; 9.41055;     -0.47856; 98.19717;80.00000;20.00000;1.00000
 90.51400; 9.48266;     -0.48206; 98.12295;80.00000;20.00000;1.00000
 91.59400; 9.55477;     -0.48516; 98.04122;80.00000;20.00000;1.00000
 92.67400; 9.62669;     -0.48773; 97.95454;80.00000;20.00000;1.00000
 93.75400; 9.69839;     -0.49012; 97.87104;80.00000;20.00000;1.00000
 94.83400; 9.77006;     -0.49330; 97.77572;80.00000;20.00000;1.00000
 95.91400; 9.84171;     -0.49523; 97.69075;80.00000;20.00000;1.00000
 96.99400; 9.91328;     -0.49729; 97.59442;80.00000;20.00000;1.00000
 98.07400; 9.98457;     -0.49905; 97.50408;80.00000;20.00000;1.00000
 99.15400;10.05588;     -0.50046; 97.40154;80.00000;20.00000;1.00000
100.23400;10.12719;     -0.50217; 97.30731;80.00000;20.00000;1.00000
101.31400;10.19861;     -0.50374; 97.21214;80.00000;20.00000;1.00000
102.39400;10.26995;     -0.50514; 97.10585;80.00000;20.00000;1.00000
103.47400;10.34131;     -0.50632; 96.99707;80.00000;20.00000;1.00000
104.55400;10.41265;     -0.50712; 96.88963;80.00000;20.00000;1.00000
105.63400;10.48405;     -0.50902; 96.78155;80.00000;20.00000;1.00000
106.71400;10.55524;     -0.51100; 96.66989;80.00000;20.00000;1.00000
107.79400;10.62653;     -0.51192; 96.55190;80.00000;20.00000;1.00000
108.87400;10.69810;     -0.51266; 96.43837;80.00000;20.00000;1.00000
109.95400;10.76998;     -0.51352; 96.33494;80.00000;20.00000;1.00000
111.03400;10.84186;     -0.51363; 96.21250;80.00000;20.00000;1.00000
112.11400;10.91373;     -0.51516; 96.10132;80.00000;20.00000;1.00000
113.19400;10.98563;     -0.51520; 95.99358;80.00000;20.00000;1.00000
114.27400;11.05768;     -0.51674; 95.88355;80.00000;20.00000;1.00000
115.35400;11.12976;     -0.51864; 95.76409;80.00000;20.00000;1.00000
116.43400;11.20196;     -0.52068; 95.65451;80.00000;20.00000;1.00000
117.51400;11.27414;     -0.52239; 95.54546;80.00000;20.00000;1.00000
118.59400;11.34638;     -0.52472; 95.43352;80.00000;20.00000;1.00000
119.67400;11.41877;     -0.52787; 95.32683;80.00000;20.00000;1.00000
120.75400;11.49134;     -0.53094; 95.21565;80.00000;20.00000;1.00000
121.83400;11.56396;     -0.53421; 95.10706;80.00000;20.00000;1.00000
122.91400;11.63675;     -0.53804; 94.99957;80.00000;20.00000;1.00000
123.99400;11.70966;     -0.54171; 94.89376;80.00000;20.00000;1.00000
125.07400;11.78280;     -0.54549; 94.78462;80.00000;20.00000;1.00000
126.15400;11.85579;     -0.54874; 94.68169;80.00000;20.00000;1.00000
127.23400;11.92880;     -0.55292; 94.56943;80.00000;20.00000;1.00000
128.31400;12.00203;     -0.55676; 94.46082;80.00000;20.00000;1.00000
129.39400;12.07544;     -0.56135; 94.35189;80.00000;20.00000;1.00000
130.47400;12.14905;     -0.56568; 94.23738;80.00000;20.00000;1.00000
131.55400;12.22272;     -0.57097; 94.13268;80.00000;20.00000;1.00000
132.63400;12.29644;     -0.57620; 94.02425;80.00000;20.00000;1.00000
133.71400;12.37033;     -0.58104; 93.89835;80.00000;20.00000;1.00000
134.79400;12.44444;     -0.58569; 93.79100;80.00000;20.00000;1.00000
135.87400;12.51888;     -0.59103; 93.67760;80.00000;20.00000;1.00000
136.95400;12.59348;     -0.59686; 93.56397;80.00000;20.00000;1.00000
138.03400;12.66812;     -0.59935; 93.45344;80.00000;20.00000;1.00000
139.11400;12.74294;     -0.60380; 93.32520;80.00000;20.00000;1.00000
140.19400;12.81806;     -0.60703; 93.20430;80.00000;20.00000;1.00000
141.27400;12.89338;     -0.61122; 93.07772;80.00000;20.00000;1.00000
142.35400;12.96895;     -0.61587; 92.95729;80.00000;20.00000;1.00000
143.43400;13.04485;     -0.62089; 92.82794;80.00000;20.00000;1.00000
144.51400;13.12102;     -0.62615; 92.69596;80.00000;20.00000;1.00000
145.59400;13.19751;     -0.63148; 92.56212;80.00000;20.00000;1.00000
146.67400;13.27432;     -0.63592; 92.43046;80.00000;20.00000;1.00000
147.75400;13.35122;     -0.63714; 92.29879;80.00000;20.00000;1.00000
148.83400;13.42833;     -0.64040; 92.15621;80.00000;20.00000;1.00000
149.91400;13.50584;     -0.64090; 92.01618;80.00000;20.00000;1.00000
150.99400;13.58366;     -0.64342; 91.87605;80.00000;20.00000;1.00000
152.07400;13.66193;     -0.63670; 91.73132;80.00000;20.00000;1.00000
153.15400;13.74059;     -0.63011; 91.58661;80.00000;20.00000;1.00000
154.23400;13.81961;     -0.63317; 91.43855;80.00000;20.00000;1.00000
155.31400;13.89905;     -0.63746; 91.28914;80.00000;20.00000;1.00000
156.39400;13.97872;     -0.64373; 91.13250;80.00000;20.00000;1.00000
157.47400;14.05870;     -0.64837; 90.97849;80.00000;20.00000;1.00000
158.55400;14.13907;     -0.65487; 90.82898;80.00000;20.00000;1.00000
159.63400;14.21990;     -0.65989; 90.66449;80.00000;20.00000;1.00000
160.71400;14.30132;     -0.66684; 90.51225;80.00000;20.00000;1.00000
161.79400;14.38311;     -0.67149; 90.34182;80.00000;20.00000;1.00000
162.87400;14.46534;     -0.67666; 90.18293;80.00000;20.00000;1.00000
163.95400;14.54802;     -0.68272; 90.02584;80.00000;20.00000;1.00000
165.03400;14.63111;     -0.68681; 89.87033;80.00000;20.00000;1.00000
166.11400;14.71454;     -0.69270; 89.69928;80.00000;20.00000;1.00000
167.19400;14.79845;     -0.70283; 89.52774;80.00000;20.00000;1.00000
168.27400;14.88293;     -0.70069; 89.36216;80.00000;20.00000;1.00000
169.35400;14.96784;     -0.70569; 89.20568;80.00000;20.00000;1.00000
170.43400;15.05345;     -0.70988; 89.03703;80.00000;20.00000;1.00000
171.51400;15.13935;     -0.71186; 88.87129;80.00000;20.00000;1.00000
172.59400;15.22582;     -0.70217; 88.70612;80.00000;20.00000;1.00000
173.67400;15.31287;     -0.70227; 88.53218;80.00000;20.00000;1.00000
174.75400;15.40023;     -0.70438; 88.37919;80.00000;20.00000;1.00000
175.83400;15.48821;     -0.70688; 88.21215;80.00000;20.00000;1.00000
176.91400;15.57667;     -0.71018; 88.03580;80.00000;20.00000;1.00000
177.99400;15.66553;     -0.71226; 87.87984;80.00000;20.00000;1.00000
179.07400;15.75480;     -0.71413; 87.71326;80.00000;20.00000;1.00000
180.15400;15.84468;     -0.71358; 87.54584;80.00000;20.00000;1.00000
181.23400;15.93511;     -0.71476; 87.38698;80.00000;20.00000;1.00000
182.31400;16.02593;     -0.71543; 87.23892;80.00000;20.00000;1.00000
183.39400;16.11710;     -0.71092; 87.06661;80.00000;20.00000;1.00000
184.47400;16.20882;     -0.71339; 86.92123;80.00000;20.00000;1.00000
185.55400;16.30164;     -0.71648; 86.77224;80.00000;20.00000;1.00000
186.63400;16.39492;     -0.72079; 86.62378;80.00000;20.00000;1.00000
187.71400;16.48846;     -0.72483; 86.48211;80.00000;20.00000;1.00000
188.79400;16.58264;     -0.72780; 86.34624;80.00000;20.00000;1.00000
189.87400;16.67742;     -0.73136; 86.20700;80.00000;20.00000;1.00000
190.95400;16.77291;     -0.73499; 86.08008;80.00000;20.00000;1.00000
192.03400;16.86880;     -0.73883; 85.94553;80.00000;20.00000;1.00000
193.11400;16.96506;     -0.74257; 85.81777;80.00000;20.00000;1.00000
194.19400;17.06218;     -0.74612; 85.70919;80.00000;20.00000;1.00000
195.27400;17.15971;     -0.74925; 85.58773;80.00000;20.00000;1.00000
196.35400;17.25781;     -0.75246; 85.48338;80.00000;20.00000;1.00000
197.43400;17.35681;     -0.75520; 85.37399;80.00000;20.00000;1.00000
198.51400;17.45646;     -0.75758; 85.26085;80.00000;20.00000;1.00000
199.59400;17.55654;     -0.75988; 85.15954;80.00000;20.00000;1.00000
200.67400;17.65728;     -0.76258; 85.05985;80.00000;20.00000;1.00000
201.75400;17.75858;     -0.76464; 84.95946;80.00000;20.00000;1.00000
202.83400;17.86068;     -0.76872; 84.85998;80.00000;20.00000;1.00000
203.91400;17.96312;     -0.77053; 84.76228;80.00000;20.00000;1.00000
204.99400;18.06584;     -0.77204; 84.66840;80.00000;20.00000;1.00000
206.07400;18.16967;     -0.77187; 84.56997;80.00000;20.00000;1.00000
207.15400;18.27423;     -0.77369; 84.47247;80.00000;20.00000;1.00000
208.23400;18.37925;     -0.77515; 84.38750;80.00000;20.00000;1.00000
209.31400;18.48484;     -0.77757; 84.28841;80.00000;20.00000;1.00000
210.39400;18.59064;     -0.77914; 84.20966;80.00000;20.00000;1.00000
211.47400;18.69719;     -0.78216; 84.11949;80.00000;20.00000;1.00000
212.55400;18.80438;     -0.78301; 84.02458;80.00000;20.00000;1.00000
213.63400;18.91185;     -0.78582; 83.94069;80.00000;20.00000;1.00000
214.71400;19.01981;     -0.78769; 83.86154;80.00000;20.00000;1.00000
215.79400;19.12865;     -0.78833; 83.77774;80.00000;20.00000;1.00000
216.87400;19.23791;     -0.79086; 83.68175;80.00000;20.00000;1.00000
217.95400;19.34754;     -0.79299; 83.60701;80.00000;20.00000;1.00000
219.03400;19.45788;     -0.79508; 83.52385;80.00000;20.00000;1.00000
220.11400;19.56875;     -0.79767; 83.44397;80.00000;20.00000;1.00000
221.19400;19.67975;     -0.79881; 83.35598;80.00000;20.00000;1.00000
222.27400;19.79132;     -0.80062; 83.27589;80.00000;20.00000;1.00000
223.35400;19.90364;     -0.80170; 83.18752;80.00000;20.00000;1.00000
224.43400;20.01609;     -0.80421; 83.10805;80.00000;20.00000;1.00000
225.51400;20.12866;     -0.80602; 83.02413;80.00000;20.00000;1.00000
226.59400;20.24222;     -0.80851; 82.94177;80.00000;20.00000;1.00000
227.67400;20.35679;     -0.81029; 82.87693;80.00000;20.00000;1.00000
228.75400;20.47111;     -0.81235; 82.78428;80.00000;20.00000;1.00000
229.83400;20.58552;     -0.81471; 82.71233;80.00000;20.00000;1.00000
230.91400;20.70069;     -0.81706; 82.62962;80.00000;20.00000;1.00000
231.99400;20.81616;     -0.81900; 82.55286;80.00000;20.00000;1.00000
233.07400;20.93174;     -0.82106; 82.47841;80.00000;20.00000;1.00000
234.15400;21.04782;     -0.82295; 82.40299;80.00000;20.00000;1.00000
235.23400;21.16402;     -0.82506; 82.31769;80.00000;20.00000;1.00000
236.31400;21.28031;     -0.82691; 82.25033;80.00000;20.00000;1.00000
237.39400;21.39690;     -0.83130; 82.17248;80.00000;20.00000;1.00000
238.47400;21.51318;     -0.83349; 82.09558;80.00000;20.00000;1.00000
239.55400;21.62962;     -0.83650; 82.01830;80.00000;20.00000;1.00000
240.63400;21.74593;     -0.83986; 81.93817;80.00000;20.00000;1.00000
241.71400;21.86225;     -0.84251; 81.86496;80.00000;20.00000;1.00000
242.79400;21.97897;     -0.84612; 81.79419;80.00000;20.00000;1.00000
243.87400;22.09575;     -0.84895; 81.72419;80.00000;20.00000;1.00000
244.95400;22.21228;     -0.85219; 81.65011;80.00000;20.00000;1.00000
246.03400;22.32891;     -0.85570; 81.56868;80.00000;20.00000;1.00000
247.11400;22.44583;     -0.85951; 81.49998;80.00000;20.00000;1.00000
248.19400;22.56253;     -0.86355; 81.43181;80.00000;20.00000;1.00000
249.27400;22.67900;     -0.86688; 81.35427;80.00000;20.00000;1.00000
250.35400;22.79561;     -0.87072; 81.29653;80.00000;20.00000;1.00000
251.43400;22.91226;     -0.87394; 81.22158;80.00000;20.00000;1.00000
252.51400;23.02856;     -0.87711; 81.13896;80.00000;20.00000;1.00000
253.59400;23.14481;     -0.88017; 81.07407;80.00000;20.00000;1.00000
254.67400;23.26143;     -0.87949; 80.99752;80.00000;20.00000;1.00000
255.75400;23.37782;     -0.88371; 80.93790;80.00000;20.00000;1.00000
256.83400;23.49404;     -0.88768; 80.87383;80.00000;20.00000;1.00000
257.91400;23.61029;     -0.89101; 80.79778;80.00000;20.00000;1.00000
258.99400;23.72639;     -0.89598; 80.72852;80.00000;20.00000;1.00000
260.07400;23.84265;     -0.89908; 80.66985;80.00000;20.00000;1.00000
261.15400;23.95845;     -0.90234; 80.59558;80.00000;20.00000;1.00000
262.23400;24.07427;     -0.90606; 80.53976;80.00000;20.00000;1.00000
263.31400;24.19063;     -0.91085; 80.47343;80.00000;20.00000;1.00000
264.39400;24.30642;     -0.91560; 80.40142;80.00000;20.00000;1.00000
265.47400;24.42162;     -0.91937; 80.33816;80.00000;20.00000;1.00000
266.55400;24.53705;     -0.92351; 80.26998;80.00000;20.00000;1.00000
267.63400;24.65261;     -0.92898; 80.21111;80.00000;20.00000;1.00000
268.71400;24.76796;     -0.93300; 80.15931;80.00000;20.00000;1.00000
269.79400;24.88340;     -0.95912; 80.09035;80.00000;20.00000;1.00000
270.87400;24.99850;     -0.96641; 80.03327;80.00000;20.00000;1.00000
271.95400;25.11321;     -0.96989; 79.97084;80.00000;20.00000;1.00000
273.03400;25.22804;     -0.97424; 79.91322;80.00000;20.00000;1.00000
274.11400;25.34278;     -0.97828; 79.84284;80.00000;20.00000;1.00000
275.19400;25.45764;     -0.98251; 79.79218;80.00000;20.00000;1.00000
276.27400;25.57219;     -0.98691; 79.73625;80.00000;20.00000;1.00000
277.35400;25.68660;     -0.99069; 79.67080;80.00000;20.00000;1.00000
278.43400;25.80112;     -0.99511; 79.61873;80.00000;20.00000;1.00000
279.51400;25.91537;     -0.99841; 79.56073;80.00000;20.00000;1.00000
280.59400;26.02929;     -1.00190; 79.50957;80.00000;20.00000;1.00000
281.67400;26.14334;     -1.00540; 79.44818;80.00000;20.00000;1.00000
282.75400;26.25752;     -1.00849; 79.39003;80.00000;20.00000;1.00000
283.83400;26.37109;     -1.01133; 79.34101;80.00000;20.00000;1.00000
284.91400;26.48436;     -1.01535; 79.27682;80.00000;20.00000;1.00000
285.99400;26.59770;     -1.01848; 79.22785;80.00000;20.00000;1.00000
287.07400;26.71122;     -1.02195; 79.17357;80.00000;20.00000;1.00000
288.15400;26.82453;     -1.02480; 79.12490;80.00000;20.00000;1.00000
289.23400;26.93766;     -1.03422; 79.07348;80.00000;20.00000;1.00000
290.31400;27.05051;     -1.03756; 79.01369;80.00000;20.00000;1.00000
291.39400;27.16314;     -1.04167; 78.97092;80.00000;20.00000;1.00000
292.47400;27.27568;     -1.04477; 78.91835;80.00000;20.00000;1.00000
293.55400;27.38824;     -1.06816; 78.86790;80.00000;20.00000;1.00000
294.63400;27.50064;     -1.07881; 78.82656;80.00000;20.00000;1.00000
295.71400;27.61274;     -1.08591; 78.77038;80.00000;20.00000;1.00000
296.79400;27.72472;     -1.09091; 78.71751;80.00000;20.00000;1.00000
297.87400;27.83667;     -1.09331; 78.67327;80.00000;20.00000;1.00000
298.95400;27.94867;     -1.11384; 78.62489;80.00000;20.00000;1.00000
300.03400;28.06033;     -1.12075; 78.57600;80.00000;20.00000;1.00000
301.11400;28.17178;     -1.12439; 78.53218;80.00000;20.00000;1.00000
302.19400;28.28344;     -1.17618; 78.49420;80.00000;20.00000;1.00000
303.27400;28.39468;     -1.18791; 78.45254;80.00000;20.00000;1.00000
304.35400;28.50570;     -1.19188; 78.40655;80.00000;20.00000;1.00000
305.43400;28.61670;     -1.19541; 78.36268;80.00000;20.00000;1.00000
306.51400;28.72770;     -1.19840; 78.31997;80.00000;20.00000;1.00000
307.59400;28.83865;     -1.20153; 78.27779;80.00000;20.00000;1.00000
308.67400;28.94910;     -1.20468; 78.24272;80.00000;20.00000;1.00000
309.75400;29.05938;     -1.21018; 78.19717;80.00000;20.00000;1.00000
310.83400;29.17001;     -1.21594; 78.15255;80.00000;20.00000;1.00000
311.91400;29.28066;     -1.22068; 78.11733;80.00000;20.00000;1.00000
312.99400;29.39082;     -1.22368; 78.07039;80.00000;20.00000;1.00000
314.07400;29.50086;     -1.22703; 78.03813;80.00000;20.00000;1.00000
315.15400;29.61093;     -1.23054; 77.99889;80.00000;20.00000;1.00000
316.23400;29.72093;     -1.23299; 77.95521;80.00000;20.00000;1.00000
317.31400;29.83118;     -1.23726; 77.92325;80.00000;20.00000;1.00000
318.39400;29.94117;     -1.24016; 77.88561;80.00000;20.00000;1.00000
319.47400;30.05085;     -1.24310; 77.84349;80.00000;20.00000;1.00000
320.55400;30.16054;     -1.24689; 77.81930;80.00000;20.00000;1.00000
321.63400;30.27023;     -1.25022; 77.78320;80.00000;20.00000;1.00000
322.71400;30.37982;     -1.25374; 77.75213;80.00000;20.00000;1.00000
323.79400;30.48928;     -1.25682; 77.71093;80.00000;20.00000;1.00000
324.87400;30.59878;     -1.26038; 77.68047;80.00000;20.00000;1.00000
325.95400;30.70814;     -1.26398; 77.64177;80.00000;20.00000;1.00000
327.03400;30.81747;     -1.26740; 77.60919;80.00000;20.00000;1.00000
328.11400;30.92662;     -1.27067; 77.57095;80.00000;20.00000;1.00000
329.19400;31.03584;     -1.27502; 77.54941;80.00000;20.00000;1.00000
330.27400;31.14493;     -1.27779; 77.51955;80.00000;20.00000;1.00000
331.35400;31.25356;     -1.28118; 77.48823;80.00000;20.00000;1.00000
332.43400;31.36247;     -1.28507; 77.45609;80.00000;20.00000;1.00000
333.51400;31.47151;     -1.28957; 77.42647;80.00000;20.00000;1.00000
334.59400;31.58041;     -1.29239; 77.39966;80.00000;20.00000;1.00000
335.67400;31.68914;     -1.29494; 77.36709;80.00000;20.00000;1.00000
336.75400;31.79793;     -1.29837; 77.32658;80.00000;20.00000;1.00000
337.83400;31.90687;     -1.30232; 77.30827;80.00000;20.00000;1.00000
338.91400;32.01521;     -1.30622; 77.27635;80.00000;20.00000;1.00000
339.99400;32.12387;     -1.30888; 77.24580;80.00000;20.00000;1.00000
341.07400;32.23273;     -1.31260; 77.21691;80.00000;20.00000;1.00000
342.15400;32.34135;     -1.31593; 77.19412;80.00000;20.00000;1.00000
343.23400;32.45020;     -1.32017; 77.16036;80.00000;20.00000;1.00000
344.31400;32.55886;     -1.32357; 77.13759;80.00000;20.00000;1.00000
345.39400;32.66739;     -1.32727; 77.12021;80.00000;20.00000;1.00000
346.47400;32.77578;     -1.33081; 77.08421;80.00000;20.00000;1.00000
347.55400;32.88433;     -1.33449; 77.05334;80.00000;20.00000;1.00000
348.63400;32.99268;     -1.33984; 77.04230;80.00000;20.00000;1.00000
349.71400;33.10090;     -1.34338; 77.01377;80.00000;20.00000;1.00000
350.79400;33.20921;     -1.34716; 76.98447;80.00000;20.00000;1.00000
351.87400;33.31765;     -1.35105; 76.96069;80.00000;20.00000;1.00000
352.95400;33.42642;     -1.35423; 76.93730;80.00000;20.00000;1.00000
354.03400;33.53512;     -1.35120; 76.90973;80.00000;20.00000;1.00000
355.11400;33.64332;     -1.35340; 76.88918;80.00000;20.00000;1.00000
356.19400;33.75140;     -1.35704; 76.86228;80.00000;20.00000;1.00000
357.27400;33.85984;     -1.36376; 76.83300;80.00000;20.00000;1.00000
358.35400;33.96849;     -1.36847; 76.81454;80.00000;20.00000;1.00000
359.43400;34.07673;     -1.37372; 76.79571;80.00000;20.00000;1.00000
360.51400;34.18483;     -1.37834; 76.77560;80.00000;20.00000;1.00000
361.59400;34.29298;     -1.38305; 76.75716;80.00000;20.00000;1.00000
362.67400;34.40149;     -1.38819; 76.73913;80.00000;20.00000;1.00000
363.75400;34.50991;     -1.39201; 76.71183;80.00000;20.00000;1.00000
364.83400;34.61784;     -1.39673; 76.69298;80.00000;20.00000;1.00000
365.91400;34.72628;     -1.40070; 76.67417;80.00000;20.00000;1.00000
366.99400;34.83484;     -1.40534; 76.65597;80.00000;20.00000;1.00000
368.07400;34.94301;     -1.41035; 76.63732;80.00000;20.00000;1.00000
369.15400;35.05127;     -1.41366; 76.61855;80.00000;20.00000;1.00000
370.23400;35.15983;     -1.41681; 76.59281;80.00000;20.00000;1.00000
371.31400;35.26806;     -1.42051; 76.57415;80.00000;20.00000;1.00000
372.39400;35.37633;     -1.42432; 76.55487;80.00000;20.00000;1.00000
373.47400;35.48480;     -1.42898; 76.53626;80.00000;20.00000;1.00000
374.55400;35.59308;     -1.43349; 76.51840;80.00000;20.00000;1.00000
375.63400;35.70140;     -1.43769; 76.50024;80.00000;20.00000;1.00000
376.71400;35.80973;     -1.44177; 76.48178;80.00000;20.00000;1.00000
377.79400;35.91794;     -1.44645; 76.46315;80.00000;20.00000;1.00000
378.87400;36.02631;     -1.45034; 76.44471;80.00000;20.00000;1.00000
379.95400;36.13467;     -1.45524; 76.42681;80.00000;20.00000;1.00000
381.03400;36.24289;     -1.45952; 76.41275;80.00000;20.00000;1.00000
382.11400;36.35090;     -1.46404; 76.39556;80.00000;20.00000;1.00000
383.19400;36.45901;     -1.46821; 76.37631;80.00000;20.00000;1.00000
384.27400;36.56728;     -1.47298; 76.35648;80.00000;20.00000;1.00000
385.35400;36.67548;     -1.47728; 76.34315;80.00000;20.00000;1.00000
386.43400;36.78375;     -1.48249; 76.32447;80.00000;20.00000;1.00000
387.51400;36.89181;     -1.48695; 76.30571;80.00000;20.00000;1.00000
388.59400;36.99999;     -1.49782; 76.28794;80.00000;20.00000;1.00000
389.67400;37.10823;     -1.50412; 76.26983;80.00000;20.00000;1.00000
390.75400;37.21621;     -1.50872; 76.25168;80.00000;20.00000;1.00000
391.83400;37.32440;     -1.51254; 76.24522;80.00000;20.00000;1.00000
392.91400;37.43282;     -1.51680; 76.22989;80.00000;20.00000;1.00000
393.99400;37.54098;     -1.52176; 76.20477;80.00000;20.00000;1.00000
395.07400;37.64897;     -1.52928; 76.18681;80.00000;20.00000;1.00000
396.15400;37.75740;     -1.53357; 76.16820;80.00000;20.00000;1.00000
397.23400;37.86582;     -1.53799; 76.15862;80.00000;20.00000;1.00000
398.31400;37.97389;     -1.54229; 76.13984;80.00000;20.00000;1.00000
399.39400;38.08209;     -1.54786; 76.12975;80.00000;20.00000;1.00000
400.47400;38.19041;     -1.55300; 76.10694;80.00000;20.00000;1.00000
401.55400;38.29882;     -1.55932; 76.08701;80.00000;20.00000;1.00000
402.63400;38.40714;     -1.56480; 76.07442;80.00000;20.00000;1.00000
403.71400;38.51511;     -1.56978; 76.06409;80.00000;20.00000;1.00000
404.79400;38.62339;     -1.57441; 76.04613;80.00000;20.00000;1.00000
405.87400;38.73150;     -1.58017; 76.02805;80.00000;20.00000;1.00000
406.95400;38.83948;     -1.58496; 76.01783;80.00000;20.00000;1.00000
408.03400;38.94771;     -1.58949; 75.99996;80.00000;20.00000;1.00000
409.11400;39.05618;     -1.59549; 75.98787;80.00000;20.00000;1.00000
410.19400;39.16460;     -1.60049; 75.97195;80.00000;20.00000;1.00000
411.27400;39.27262;     -1.60657; 75.94551;80.00000;20.00000;1.00000
412.35400;39.38081;     -1.61267; 75.92648;80.00000;20.00000;1.00000
413.43400;39.48884;     -1.61847; 75.91657;80.00000;20.00000;1.00000
414.51400;39.59680;     -1.62346; 75.90633;80.00000;20.00000;1.00000
415.59400;39.70525;     -1.62683; 75.88806;80.00000;20.00000;1.00000
416.67400;39.81354;     -1.63471; 75.87004;80.00000;20.00000;1.00000
417.75400;39.92148;     -1.64258; 75.85979;80.00000;20.00000;1.00000
418.83400;40.02948;     -1.64878; 75.84217;80.00000;20.00000;1.00000
419.91400;40.13767;     -1.65813; 75.82938;80.00000;20.00000;1.00000
420.99400;40.24590;     -1.66902; 75.81409;80.00000;20.00000;1.00000
422.07400;40.35419;     -1.68187; 75.78615;80.00000;20.00000;1.00000
423.15400;40.46258;     -1.69635; 75.76881;80.00000;20.00000;1.00000
424.23400;40.57065;     -1.71449; 75.74150;80.00000;20.00000;1.00000
425.31400;40.67887;     -1.73139; 75.73602;80.00000;20.00000;1.00000
426.39400;40.78707;     -1.74848; 75.72114;80.00000;20.00000;1.00000
427.47400;40.89523;     -1.76420; 75.70325;80.00000;20.00000;1.00000
428.55400;41.00370;     -1.77870; 75.68551;80.00000;20.00000;1.00000
429.63400;41.11172;     -1.78923; 75.66637;80.00000;20.00000;1.00000
430.71400;41.21985;     -1.79922; 75.65696;80.00000;20.00000;1.00000
431.79400;41.32811;     -1.80580; 75.63938;80.00000;20.00000;1.00000
432.87400;41.43624;     -1.81199; 75.62932;80.00000;20.00000;1.00000
433.95400;41.54445;     -1.81508; 75.61151;80.00000;20.00000;1.00000
435.03400;41.65283;     -1.81894; 75.60184;80.00000;20.00000;1.00000
436.11400;41.76131;     -1.82096; 75.59205;80.00000;20.00000;1.00000
437.19400;41.86956;     -1.82187; 75.59031;80.00000;20.00000;1.00000
438.27400;41.97778;     -1.82267; 75.58070;80.00000;20.00000;1.00000
439.35400;42.08608;     -1.82428; 75.56271;80.00000;20.00000;1.00000
440.43400;42.19444;     -1.82615; 75.55304;80.00000;20.00000;1.00000
441.51400;42.30297;     -1.82793; 75.54341;80.00000;20.00000;1.00000
442.59400;42.41134;     -1.82895; 75.54156;80.00000;20.00000;1.00000
443.67400;42.51960;     -1.83110; 75.53187;80.00000;20.00000;1.00000
444.75400;42.62795;     -1.83251; 75.51512;80.00000;20.00000;1.00000
445.83400;42.73628;     -1.83460; 75.51247;80.00000;20.00000;1.00000
446.91400;42.84470;     -1.83713; 75.50288;80.00000;20.00000;1.00000
447.99400;42.95297;     -1.83912; 75.50148;80.00000;20.00000;1.00000
449.07400;43.06132;     -1.84161; 75.48339;80.00000;20.00000;1.00000
450.15400;43.16971;     -1.84479; 75.47372;80.00000;20.00000;1.00000
451.23400;43.27805;     -1.84738; 75.47203;80.00000;20.00000;1.00000
452.31400;43.38661;     -1.85107; 75.47045;80.00000;20.00000;1.00000
453.39400;43.49498;     -1.85468; 75.46241;80.00000;20.00000;1.00000
454.47400;43.60316;     -1.85818; 75.45061;80.00000;20.00000;1.00000
455.55400;43.71161;     -1.86120; 75.44153;80.00000;20.00000;1.00000
456.63400;43.82022;     -1.86492; 75.43786;80.00000;20.00000;1.00000
457.71400;43.92859;     -1.86743; 75.43040;80.00000;20.00000;1.00000
458.79400;44.03684;     -1.86958; 75.42065;80.00000;20.00000;1.00000
459.87400;44.14529;     -1.87256; 75.41124;80.00000;20.00000;1.00000
460.95400;44.25383;     -1.86858; 75.41002;80.00000;20.00000;1.00000
462.03400;44.36222;     -1.86482; 75.40003;80.00000;20.00000;1.00000
463.11400;44.47037;     -1.86933; 75.39233;80.00000;20.00000;1.00000
464.19400;44.57859;     -1.87274; 75.39086;80.00000;20.00000;1.00000
465.27400;44.68689;     -1.87682; 75.38912;80.00000;20.00000;1.00000
466.35400;44.79536;     -1.88085; 75.37761;80.00000;20.00000;1.00000
467.43400;44.90374;     -1.88624; 75.37012;80.00000;20.00000;1.00000
468.51400;45.01184;     -1.89149; 75.36846;80.00000;20.00000;1.00000
469.59400;45.12020;     -1.89607; 75.36500;80.00000;20.00000;1.00000
470.67400;45.22864;     -1.90090; 75.35991;80.00000;20.00000;1.00000
471.75400;45.33702;     -1.90625; 75.35398;80.00000;20.00000;1.00000
472.83400;45.44549;     -1.91139; 75.34448;80.00000;20.00000;1.00000
473.91400;45.55372;     -1.91712; 75.33489;80.00000;20.00000;1.00000
474.99400;45.66183;     -1.92189; 75.33359;80.00000;20.00000;1.00000
476.07400;45.77007;     -1.92721; 75.32390;80.00000;20.00000;1.00000
477.15400;45.87858;     -1.93258; 75.32249;80.00000;20.00000;1.00000
478.23400;45.98718;     -1.93774; 75.31308;80.00000;20.00000;1.00000
479.31400;46.09542;     -1.94397; 75.31158;80.00000;20.00000;1.00000
480.39400;46.20366;     -1.94880; 75.30214;80.00000;20.00000;1.00000
481.47400;46.31217;     -1.95495; 75.30070;80.00000;20.00000;1.00000
482.55400;46.42052;     -1.95978; 75.29126;80.00000;20.00000;1.00000
483.63400;46.52893;     -1.96628; 75.28989;80.00000;20.00000;1.00000
484.71400;46.63728;     -1.97269; 75.28845;80.00000;20.00000;1.00000
485.79400;46.74577;     -1.97802; 75.28710;80.00000;20.00000;1.00000
486.87400;46.85433;     -1.98060; 75.27753;80.00000;20.00000;1.00000
487.95400;46.96250;     -1.98466; 75.26821;80.00000;20.00000;1.00000
489.03400;47.07104;     -1.99073; 75.26692;80.00000;20.00000;1.00000
490.11400;47.17933;     -1.99675; 75.26552;80.00000;20.00000;1.00000
491.19400;47.28744;     -2.00191; 75.25597;80.00000;20.00000;1.00000
492.27400;47.39584;     -2.00777; 75.24626;80.00000;20.00000;1.00000
493.35400;47.50421;     -2.01364; 75.24586;80.00000;20.00000;1.00000
494.43400;47.61241;     -2.01825; 75.23600;80.00000;20.00000;1.00000
495.51400;47.72042;     -2.02480; 75.23049;80.00000;20.00000;1.00000
496.59400;47.82858;     -2.02883; 75.22910;80.00000;20.00000;1.00000
497.67400;47.93688;     -2.03432; 75.22776;80.00000;20.00000;1.00000
498.75400;48.04560;     -2.03991; 75.22274;80.00000;20.00000;1.00000
499.83400;48.15420;     -2.04639; 75.21913;80.00000;20.00000;1.00000
500.91400;48.26234;     -2.05148; 75.21205;80.00000;20.00000;1.00000
501.99400;48.37038;     -2.05767; 75.21069;80.00000;20.00000;1.00000
503.07400;48.47848;     -2.06393; 75.20122;80.00000;20.00000;1.00000
504.15400;48.58675;     -2.06887; 75.19206;80.00000;20.00000;1.00000
505.23400;48.69509;     -2.07242; 75.18913;80.00000;20.00000;1.00000
506.31400;48.80349;     -2.07705; 75.18154;80.00000;20.00000;1.00000
507.39400;48.91172;     -2.08235; 75.18031;80.00000;20.00000;1.00000
508.47400;49.01963;     -2.08837; 75.16924;80.00000;20.00000;1.00000
509.55400;49.12764;     -2.09408; 75.16160;80.00000;20.00000;1.00000
510.63400;49.23575;     -2.10017; 75.16048;80.00000;20.00000;1.00000
511.71400;49.34389;     -2.10631; 75.15129;80.00000;20.00000;1.00000
512.79400;49.45239;     -2.11196; 75.14992;80.00000;20.00000;1.00000
513.87400;49.56079;     -2.11713; 75.14885;80.00000;20.00000;1.00000
514.95400;49.66900;     -2.12242; 75.14353;80.00000;20.00000;1.00000
516.03400;49.77720;     -2.12740; 75.13581;80.00000;20.00000;1.00000
517.11400;49.88533;     -2.13474; 75.13314;80.00000;20.00000;1.00000
518.19400;49.99360;     -2.14117; 75.13201;80.00000;20.00000;1.00000
519.27400;50.10187;     -2.14716; 75.12281;80.00000;20.00000;1.00000
520.35400;50.21018;     -2.15306; 75.11365;80.00000;20.00000;1.00000
521.43400;50.31837;     -2.15778; 75.11251;80.00000;20.00000;1.00000
522.51400;50.42636;     -2.16303; 75.10434;80.00000;20.00000;1.00000
523.59400;50.53473;     -2.16778; 75.10271;80.00000;20.00000;1.00000
524.67400;50.64311;     -2.17370; 75.09305;80.00000;20.00000;1.00000
525.75400;50.75138;     -2.17861; 75.09194;80.00000;20.00000;1.00000
526.83400;50.85955;     -2.18412; 75.08276;80.00000;20.00000;1.00000
527.91400;50.96772;     -2.18953; 75.08168;80.00000;20.00000;1.00000
528.99400;51.07576;     -2.19467; 75.08052;80.00000;20.00000;1.00000
530.07400;51.18395;     -2.19837; 75.07085;80.00000;20.00000;1.00000
531.15400;51.29230;     -2.20390; 75.07025;80.00000;20.00000;1.00000
532.23400;51.40061;     -2.20827; 75.06934;80.00000;20.00000;1.00000
533.31400;51.50865;     -2.21236; 75.06015;80.00000;20.00000;1.00000
534.39400;51.61680;     -2.21719; 75.05905;80.00000;20.00000;1.00000
535.47400;51.72518;     -2.22264; 75.04979;80.00000;20.00000;1.00000
536.55400;51.83347;     -2.22708; 75.04896;80.00000;20.00000;1.00000
537.63400;51.94153;     -2.23263; 75.03986;80.00000;20.00000;1.00000
538.71400;52.04957;     -2.23644; 75.03881;80.00000;20.00000;1.00000
539.79400;52.15763;     -2.24173; 75.02979;80.00000;20.00000;1.00000
540.87400;52.26577;     -2.24767; 75.02869;80.00000;20.00000;1.00000
541.95400;52.37398;     -2.25265; 75.01968;80.00000;20.00000;1.00000
543.03400;52.48206;     -2.25790; 75.02341;80.00000;20.00000;1.00000
544.11400;52.59006;     -2.26199; 75.01757;80.00000;20.00000;1.00000
545.19400;52.69795;     -2.26803; 75.00849;80.00000;20.00000;1.00000
546.27400;52.80599;     -2.27215; 75.00758;80.00000;20.00000;1.00000
547.35400;52.91420;     -2.27711; 75.00652;80.00000;20.00000;1.00000
548.43400;53.02257;     -2.28127; 74.99739;80.00000;20.00000;1.00000
549.51400;53.13077;     -2.28640; 74.99664;80.00000;20.00000;1.00000
550.59400;53.23880;     -2.29281; 74.98768;80.00000;20.00000;1.00000
551.67400;53.34691;     -2.29821; 74.97869;80.00000;20.00000;1.00000
552.75400;53.45482;     -2.30190; 74.97773;80.00000;20.00000;1.00000
553.83400;53.56258;     -2.30606; 74.97654;80.00000;20.00000;1.00000
554.91400;53.67067;     -2.31047; 74.96789;80.00000;20.00000;1.00000
555.99400;53.77877;     -2.31663; 74.97274;80.00000;20.00000;1.00000
557.07400;53.88682;     -2.32150; 74.97187;80.00000;20.00000;1.00000
558.15400;53.99482;     -2.32473; 74.96251;80.00000;20.00000;1.00000
559.23400;54.10294;     -2.32908; 74.95404;80.00000;20.00000;1.00000
560.31400;54.21101;     -2.34128; 74.94510;80.00000;20.00000;1.00000
561.39400;54.31914;     -2.34561; 74.95214;80.00000;20.00000;1.00000
562.47400;54.42722;     -2.35017; 74.93607;80.00000;20.00000;1.00000
563.55400;54.53532;     -2.35287; 74.92845;80.00000;20.00000;1.00000
564.63400;54.64342;     -2.35784; 74.92756;80.00000;20.00000;1.00000
565.71400;54.75140;     -2.36253; 74.92665;80.00000;20.00000;1.00000
566.79400;54.85933;     -2.36528; 74.92574;80.00000;20.00000;1.00000
567.87400;54.96757;     -2.37019; 74.93095;80.00000;20.00000;1.00000
568.95400;55.07539;     -2.37393; 74.92199;80.00000;20.00000;1.00000
570.03400;55.18288;     -2.37808; 74.91233;80.00000;20.00000;1.00000
571.11400;55.29082;     -2.38185; 74.90420;80.00000;20.00000;1.00000
572.19400;55.39855;     -2.38532; 74.90332;80.00000;20.00000;1.00000
573.27400;55.50640;     -2.38978; 74.89449;80.00000;20.00000;1.00000
574.35400;55.61454;     -2.39164; 74.90168;80.00000;20.00000;1.00000
575.43400;55.72232;     -2.39582; 74.89287;80.00000;20.00000;1.00000
576.51400;55.83007;     -2.39884; 74.89994;80.00000;20.00000;1.00000
577.59400;55.93822;     -2.40152; 74.89112;80.00000;20.00000;1.00000
578.67400;56.04624;     -2.40473; 74.88249;80.00000;20.00000;1.00000
579.75400;56.15402;     -2.40773; 74.87569;80.00000;20.00000;1.00000
580.83400;56.26179;     -2.41151; 74.87476;80.00000;20.00000;1.00000
581.91400;56.36971;     -2.41466; 74.86616;80.00000;20.00000;1.00000
582.99400;56.47763;     -2.41724; 74.86327;80.00000;20.00000;1.00000
584.07400;56.58559;     -2.41982; 74.85653;80.00000;20.00000;1.00000
585.15400;56.69348;     -2.42329; 74.85565;80.00000;20.00000;1.00000
586.23400;56.80153;     -2.42642; 74.85507;80.00000;20.00000;1.00000
587.31400;56.90966;     -2.43060; 74.85228;80.00000;20.00000;1.00000
588.39400;57.01740;     -2.43274; 74.84712;80.00000;20.00000;1.00000
589.47400;57.12502;     -2.43526; 74.84267;80.00000;20.00000;1.00000
590.55400;57.23319;     -2.43826; 74.85021;80.00000;20.00000;1.00000
591.63400;57.34147;     -2.44132; 74.84139;80.00000;20.00000;1.00000
592.71400;57.44948;     -2.44433; 74.83278;80.00000;20.00000;1.00000
593.79400;57.55745;     -2.44838; 74.82407;80.00000;20.00000;1.00000
594.87400;57.66564;     -2.44364; 74.81752;80.00000;20.00000;1.00000
595.95400;57.77376;     -2.44424; 74.81666;80.00000;20.00000;1.00000
597.03400;57.88180;     -2.44771; 74.81407;80.00000;20.00000;1.00000
598.11400;57.98993;     -2.44934; 74.80535;80.00000;20.00000;1.00000
599.19400;58.09797;     -2.45209; 74.80467;80.00000;20.00000;1.00000
600.27400;58.20594;     -2.45378; 74.80404;80.00000;20.00000;1.00000
601.35400;58.31386;     -2.45737; 74.79536;80.00000;20.00000;1.00000
602.43400;58.42193;     -2.45994; 74.79470;80.00000;20.00000;1.00000
603.51400;58.53006;     -2.46122; 74.78807;80.00000;20.00000;1.00000
604.59400;58.63797;     -2.46489; 74.78546;80.00000;20.00000;1.00000
605.67400;58.74583;     -2.46850; 74.78258;80.00000;20.00000;1.00000
606.75400;58.85381;     -2.47191; 74.78414;80.00000;20.00000;1.00000
607.83400;58.96180;     -2.47452; 74.77551;80.00000;20.00000;1.00000
608.91400;59.06965;     -2.47731; 74.78289;80.00000;20.00000;1.00000
609.99400;59.17759;     -2.47933; 74.77433;80.00000;20.00000;1.00000
611.07400;59.28561;     -2.48126; 74.76963;80.00000;20.00000;1.00000
612.15400;59.39383;     -2.48427; 74.76914;80.00000;20.00000;1.00000
613.23400;59.50189;     -2.48606; 74.76454;80.00000;20.00000;1.00000
614.31400;59.60976;     -2.48854; 74.76390;80.00000;20.00000;1.00000
615.39400;59.71784;     -2.49174; 74.76333;80.00000;20.00000;1.00000
616.47400;59.82572;     -2.49411; 74.75474;80.00000;20.00000;1.00000
617.55400;59.93346;     -2.49572; 74.74614;80.00000;20.00000;1.00000
618.63400;60.04150;     -2.49734; 74.75357;80.00000;20.00000;1.00000
619.71400;60.14976;     -2.50009; 74.74908;80.00000;20.00000;1.00000
620.79400;60.25790;     -2.50193; 74.74459;80.00000;20.00000;1.00000
621.87400;60.36572;     -2.50288; 74.73795;80.00000;20.00000;1.00000
622.95400;60.47346;     -2.50349; 74.73743;80.00000;20.00000;1.00000
624.03400;60.58135;     -2.50484; 74.73489;80.00000;20.00000;1.00000
625.11400;60.68924;     -2.50655; 74.72836;80.00000;20.00000;1.00000
626.19400;60.79733;     -2.50834; 74.72785;80.00000;20.00000;1.00000
627.27400;60.90550;     -2.51068; 74.72743;80.00000;20.00000;1.00000
628.35400;61.01345;     -2.51253; 74.72481;80.00000;20.00000;1.00000
629.43400;61.12128;     -2.51675; 74.72431;80.00000;20.00000;1.00000
630.51400;61.22931;     -2.51862; 74.71585;80.00000;20.00000;1.00000
631.59400;61.33740;     -2.52103; 74.71540;80.00000;20.00000;1.00000
632.67400;61.44535;     -2.52206; 74.70681;80.00000;20.00000;1.00000
633.75400;61.55332;     -2.52401; 74.71443;80.00000;20.00000;1.00000
634.83400;61.66159;     -2.52556; 74.71442;80.00000;20.00000;1.00000
635.91400;61.76975;     -2.52641; 74.71355;80.00000;20.00000;1.00000
636.99400;61.87766;     -2.52824; 74.70495;80.00000;20.00000;1.00000
638.07400;61.98553;     -2.52954; 74.69661;80.00000;20.00000;1.00000
639.15400;62.09357;     -2.53149; 74.69620;80.00000;20.00000;1.00000
640.23400;62.20143;     -2.53342; 74.69568;80.00000;20.00000;1.00000
641.31400;62.30939;     -2.53516; 74.69523;80.00000;20.00000;1.00000
642.39400;62.41768;     -2.53782; 74.69490;80.00000;20.00000;1.00000
643.47400;62.52570;     -2.53158; 74.68648;80.00000;20.00000;1.00000
644.55400;62.63374;     -2.53233; 74.68610;80.00000;20.00000;1.00000
645.63400;62.74162;     -2.53393; 74.66965;80.00000;20.00000;1.00000
646.71400;62.84956;     -2.53560; 74.67717;80.00000;20.00000;1.00000
647.79400;62.95791;     -2.53709; 74.67685;80.00000;20.00000;1.00000
648.87400;63.06609;     -2.53779; 74.66853;80.00000;20.00000;1.00000
649.95400;63.17398;     -2.53944; 74.66812;80.00000;20.00000;1.00000
651.03400;63.28210;     -2.54082; 74.65970;80.00000;20.00000;1.00000
652.11400;63.39014;     -2.54250; 74.65938;80.00000;20.00000;1.00000
653.19400;63.49792;     -2.54256; 74.65893;80.00000;20.00000;1.00000
654.27400;63.60571;     -2.54471; 74.65848;80.00000;20.00000;1.00000
655.35400;63.71350;     -2.54594; 74.64987;80.00000;20.00000;1.00000
656.43400;63.82138;     -2.54778; 74.64979;80.00000;20.00000;1.00000
657.51400;63.92936;     -2.54874; 74.64948;80.00000;20.00000;1.00000
658.59400;64.03741;     -2.55021; 74.64114;80.00000;20.00000;1.00000
659.67400;64.14558;     -2.55070; 74.64086;80.00000;20.00000;1.00000
660.75400;64.25362;     -2.55287; 74.64054;80.00000;20.00000;1.00000
661.83400;64.36149;     -2.55422; 74.64020;80.00000;20.00000;1.00000
662.91400;64.46938;     -2.55548; 74.63785;80.00000;20.00000;1.00000
663.99400;64.57759;     -2.55721; 74.63158;80.00000;20.00000;1.00000
665.07400;64.68590;     -2.55811; 74.62344;80.00000;20.00000;1.00000
666.15400;64.79393;     -2.55989; 74.62302;80.00000;20.00000;1.00000
667.23400;64.90175;     -2.55924; 74.62269;80.00000;20.00000;1.00000
668.31400;65.00986;     -2.55886; 74.61442;80.00000;20.00000;1.00000
669.39400;65.11795;     -2.55968; 74.61412;80.00000;20.00000;1.00000
670.47400;65.22587;     -2.56039; 74.61385;80.00000;20.00000;1.00000
671.55400;65.33398;     -2.56109; 74.61363;80.00000;20.00000;1.00000
672.63400;65.44214;     -2.56246; 74.61333;80.00000;20.00000;1.00000
673.71400;65.55031;     -2.56408; 74.60704;80.00000;20.00000;1.00000
674.79400;65.65821;     -2.56389; 74.60486;80.00000;20.00000;1.00000
675.87400;65.76607;     -2.56497; 74.59652;80.00000;20.00000;1.00000
676.95400;65.87400;     -2.56504; 74.59632;80.00000;20.00000;1.00000
678.03400;65.98187;     -2.56626; 74.59609;80.00000;20.00000;1.00000
679.11400;66.08988;     -2.56707; 74.59584;80.00000;20.00000;1.00000
680.19400;66.19790;     -2.56801; 74.58858;80.00000;20.00000;1.00000
681.27400;66.30593;     -2.56883; 74.58722;80.00000;20.00000;1.00000
682.35400;66.41388;     -2.56944; 74.58911;80.00000;20.00000;1.00000
683.43400;66.52169;     -2.56983; 74.58889;80.00000;20.00000;1.00000
684.51400;66.62948;     -2.57093; 74.58060;80.00000;20.00000;1.00000
685.59400;66.73732;     -2.57187; 74.57453;80.00000;20.00000;1.00000
686.67400;66.84531;     -2.57211; 74.57429;80.00000;20.00000;1.00000
687.75400;66.95325;     -2.57510; 74.57418;80.00000;20.00000;1.00000
688.83400;67.06090;     -2.57366; 74.57193;80.00000;20.00000;1.00000
689.91400;67.16874;     -2.57358; 74.57166;80.00000;20.00000;1.00000
690.99400;67.27688;     -2.57386; 74.55642;80.00000;20.00000;1.00000
692.07400;67.38493;     -2.57443; 74.55536;80.00000;20.00000;1.00000
693.15400;67.49277;     -2.57482; 74.55530;80.00000;20.00000;1.00000
694.23400;67.60058;     -2.57577; 74.56306;80.00000;20.00000;1.00000
695.31400;67.70858;     -2.57616; 74.55493;80.00000;20.00000;1.00000
696.39400;67.81645;     -2.57709; 74.54677;80.00000;20.00000;1.00000
697.47400;67.92435;     -2.57760; 74.54900;80.00000;20.00000;1.00000
698.55400;68.03214;     -2.57858; 74.55345;80.00000;20.00000;1.00000
699.63400;68.13989;     -2.57940; 74.53832;80.00000;20.00000;1.00000
700.71400;68.24775;     -2.57909; 74.53817;80.00000;20.00000;1.00000
701.79400;68.35548;     -2.57980; 74.52984;80.00000;20.00000;1.00000
702.87400;68.46347;     -2.57971; 74.53005;80.00000;20.00000;1.00000
703.95400;68.57167;     -2.58116; 74.52198;80.00000;20.00000;1.00000
705.03400;68.67975;     -2.58103; 74.52984;80.00000;20.00000;1.00000
706.11400;68.78769;     -2.58190; 74.52514;80.00000;20.00000;1.00000
707.19400;68.89533;     -2.58274; 74.52165;80.00000;20.00000;1.00000
708.27400;69.00308;     -2.58323; 74.52155;80.00000;20.00000;1.00000
709.35400;69.11099;     -2.58336; 74.51548;80.00000;20.00000;1.00000
710.43400;69.21890;     -2.58455; 74.51541;80.00000;20.00000;1.00000
711.51400;69.32703;     -2.58532; 74.51335;80.00000;20.00000;1.00000
712.59400;69.43491;     -2.58541; 74.50532;80.00000;20.00000;1.00000
713.67400;69.54275;     -2.58668; 74.50528;80.00000;20.00000;1.00000
714.75400;69.65056;     -2.58735; 74.49706;80.00000;20.00000;1.00000
715.83400;69.75827;     -2.58761; 74.50208;80.00000;20.00000;1.00000
716.91400;69.86603;     -2.58869; 74.49697;80.00000;20.00000;1.00000
717.99400;69.97406;     -2.58888; 74.49674;80.00000;20.00000;1.00000
719.07400;70.08212;     -2.58932; 74.48103;80.00000;20.00000;1.00000
720.15400;70.18977;     -2.58996; 74.48099;80.00000;20.00000;1.00000
721.23400;70.29747;     -2.59103; 74.47295;80.00000;20.00000;1.00000
722.31400;70.40535;     -2.59063; 74.46681;80.00000;20.00000;1.00000
723.39400;70.51321;     -2.59157; 74.46510;80.00000;20.00000;1.00000
724.47400;70.62117;     -2.59090; 74.46145;80.00000;20.00000;1.00000
725.55400;70.72922;     -2.59257; 74.46495;80.00000;20.00000;1.00000
726.63400;70.83693;     -2.59288; 74.46487;80.00000;20.00000;1.00000
727.71400;70.94454;     -2.59284; 74.45691;80.00000;20.00000;1.00000
728.79400;71.05240;     -2.59337; 74.45683;80.00000;20.00000;1.00000
729.87400;71.16036;     -2.59413; 74.44893;80.00000;20.00000;1.00000
730.95400;71.26814;     -2.59466; 74.44091;80.00000;20.00000;1.00000
732.03400;71.37586;     -2.59608; 74.43693;80.00000;20.00000;1.00000
733.11400;71.48376;     -2.59722; 74.43729;80.00000;20.00000;1.00000
734.19400;71.59155;     -2.59631; 74.43310;80.00000;20.00000;1.00000
735.27400;71.69931;     -2.59733; 74.42913;80.00000;20.00000;1.00000
736.35400;71.80715;     -2.59815; 74.42522;80.00000;20.00000;1.00000
737.43400;71.91497;     -2.59792; 74.41655;80.00000;20.00000;1.00000
738.51400;72.02277;     -2.59832; 74.41258;80.00000;20.00000;1.00000
739.59400;72.13064;     -2.59825; 74.41269;80.00000;20.00000;1.00000
740.67400;72.23864;     -2.59847; 74.41279;80.00000;20.00000;1.00000
741.75400;72.34662;     -2.59919; 74.40910;80.00000;20.00000;1.00000
742.83400;72.45450;     -2.59950; 74.40905;80.00000;20.00000;1.00000
743.91400;72.56237;     -2.60003; 74.39265;80.00000;20.00000;1.00000
744.99400;72.67013;     -2.60043; 74.39322;80.00000;20.00000;1.00000
746.07400;72.77809;     -2.60122; 74.39319;80.00000;20.00000;1.00000
747.15400;72.88602;     -2.60169; 74.38541;80.00000;20.00000;1.00000
748.23400;72.99383;     -2.60176; 74.38952;80.00000;20.00000;1.00000
749.31400;73.10184;     -2.60244; 74.38172;80.00000;20.00000;1.00000
750.39400;73.20963;     -2.60310; 74.37385;80.00000;20.00000;1.00000
751.47400;73.31747;     -2.60258; 74.37397;80.00000;20.00000;1.00000
752.55400;73.42542;     -2.60422; 74.37192;80.00000;20.00000;1.00000
753.63400;73.53319;     -2.60441; 74.36620;80.00000;20.00000;1.00000
754.71400;73.64104;     -2.60433; 74.35582;80.00000;20.00000;1.00000
755.79400;73.74906;     -2.60477; 74.35058;80.00000;20.00000;1.00000
756.87400;73.85715;     -2.60559; 74.35080;80.00000;20.00000;1.00000
757.95400;73.96508;     -2.60742; 74.34288;80.00000;20.00000;1.00000
759.03400;74.07294;     -2.60372; 74.33527;80.00000;20.00000;1.00000
760.11400;74.18101;     -2.60254; 74.33533;80.00000;20.00000;1.00000
761.19400;74.28883;     -2.60281; 74.32744;80.00000;20.00000;1.00000
762.27400;74.39683;     -2.60312; 74.32765;80.00000;20.00000;1.00000
763.35400;74.50483;     -2.60351; 74.32787;80.00000;20.00000;1.00000
764.43400;74.61266;     -2.60382; 74.31209;80.00000;20.00000;1.00000
765.51400;74.72065;     -2.60355; 74.31230;80.00000;20.00000;1.00000
766.59400;74.82873;     -2.60437; 74.30452;80.00000;20.00000;1.00000
767.67400;74.93674;     -2.60480; 74.30472;80.00000;20.00000;1.00000
768.75400;75.04463;     -2.60492; 74.29689;80.00000;20.00000;1.00000
769.83400;75.15272;     -2.60525; 74.29716;80.00000;20.00000;1.00000
770.91400;75.26067;     -2.60594; 74.28347;80.00000;20.00000;1.00000
771.99400;75.36852;     -2.60573; 74.28158;80.00000;20.00000;1.00000
773.07400;75.47648;     -2.60655; 74.28182;80.00000;20.00000;1.00000
774.15400;75.58448;     -2.60673; 74.27419;80.00000;20.00000;1.00000
775.23400;75.69254;     -2.60658; 74.26635;80.00000;20.00000;1.00000
776.31400;75.80053;     -2.60694; 74.26660;80.00000;20.00000;1.00000
777.39400;75.90847;     -2.60788; 74.25071;80.00000;20.00000;1.00000
778.47400;76.01646;     -2.60720; 74.25111;80.00000;20.00000;1.00000
779.55400;76.12461;     -2.60747; 74.24341;80.00000;20.00000;1.00000
780.63400;76.23272;     -2.60715; 74.23576;80.00000;20.00000;1.00000
781.71400;76.34061;     -2.60723; 74.22181;80.00000;20.00000;1.00000
782.79400;76.44842;     -2.60728; 74.22422;80.00000;20.00000;1.00000
783.87400;76.55632;     -2.60730; 74.21765;80.00000;20.00000;1.00000
784.95400;76.66433;     -2.60807; 74.20876;80.00000;20.00000;1.00000
786.03400;76.77223;     -2.60872; 74.20904;80.00000;20.00000;1.00000
787.11400;76.88017;     -2.60891; 74.20134;80.00000;20.00000;1.00000
788.19400;76.98842;     -2.60907; 74.19368;80.00000;20.00000;1.00000
789.27400;77.09639;     -2.60921; 74.19405;80.00000;20.00000;1.00000
790.35400;77.20428;     -2.60968; 74.18641;80.00000;20.00000;1.00000
791.43400;77.31227;     -2.61058; 74.17875;80.00000;20.00000;1.00000
792.51400;77.42006;     -2.61072; 74.17093;80.00000;20.00000;1.00000
793.59400;77.52777;     -2.61114; 74.17131;80.00000;20.00000;1.00000
794.67400;77.63573;     -2.61101; 74.16359;80.00000;20.00000;1.00000
795.75400;77.74369;     -2.61193; 74.15591;80.00000;20.00000;1.00000
796.83400;77.85158;     -2.61257; 74.15035;80.00000;20.00000;1.00000
797.91400;77.95957;     -2.61187; 74.14882;80.00000;20.00000;1.00000
798.31400;77.99989;     -2.61186; 74.14076;80.00000;20.00000;1.00000